Exception has occurred: DeadlockDetectedException
DeadLock detected from rank: 0 
 Traceback (most recent call last):
  File "/home/jiale/anaconda3/envs/nuplan/lib/python3.9/site-packages/pytorch_lightning/trainer/trainer.py", line 871, in run_train
    self.train_loop.run_training_epoch()
  File "/home/jiale/anaconda3/envs/nuplan/lib/python3.9/site-packages/pytorch_lightning/trainer/training_loop.py", line 584, in run_training_epoch
    self.trainer.run_evaluation(on_epoch=True)
  File "/home/jiale/anaconda3/envs/nuplan/lib/python3.9/site-packages/pytorch_lightning/trainer/trainer.py", line 954, in run_evaluation
    for batch_idx, batch in enumerate(dataloader):
  File "/home/jiale/anaconda3/envs/nuplan/lib/python3.9/site-packages/torch/utils/data/dataloader.py", line 521, in __next__
    data = self._next_data()
  File "/home/jiale/anaconda3/envs/nuplan/lib/python3.9/site-packages/torch/utils/data/dataloader.py", line 1186, in _next_data
    idx, data = self._get_data()
  File "/home/jiale/anaconda3/envs/nuplan/lib/python3.9/site-packages/torch/utils/data/dataloader.py", line 1147, in _get_data
    raise RuntimeError('Pin memory thread exited unexpectedly')
RuntimeError: Pin memory thread exited unexpectedly

During handling of the above exception, another exception occurred:

  File "/home/jiale/Documents/master/nuplan-devkit/nuplan/planning/script/run_training.py", line 66, in main
    engine.trainer.fit(model=engine.model, datamodule=engine.datamodule)
  File "/home/jiale/Documents/master/nuplan-devkit/scripts/train_autobots.py", line 57, in train_autobots
    engine=main_train(cfg)
  File "/home/jiale/Documents/master/nuplan-devkit/scripts/train_autobots.py", line 94, in <module>
    train_autobots(train_dict)